Workbook

Sheet Datos
A1: id | B1: fecha_commit | C1: fecha_despliegue | D1: exitoso | E1: horas_recuperacion | F1: Lead time (h) | G1: Día despliegue (1=Lun…7=Dom) | H1: Día (nombre) | J1: Leyenda
A2: 1 | B2: 46265.995 | C2: 46266.578 | D2: si | E2: 0 | F2: =ROUND((C2-B2)*24,2) -> 14 | G2: =WEEKDAY(C2,2) -> 2 | H2: =CHOOSE(G2,"Lunes","Martes","Miércoles","Jueves","Viernes","Sábado","Domingo") -> Martes | J2: Azul = datos de entrada (datos/despliegues.csv, simulados por el docente).
A3: 2 | B3: 46267.864 | C3: 46268.114 | D3: si | E3: 0 | F3: =ROUND((C3-B3)*24,2) -> 6 | G3: =WEEKDAY(C3,2) -> 4 | H3: =CHOOSE(G3,"Lunes","Martes","Miércoles","Jueves","Viernes","Sábado","Domingo") -> Jueves | J3: Negro = fórmulas calculadas.
A4: 3 | B4: 46269.036 | C4: 46269.453 | D4: no | E4: 5 | F4: =ROUND((C4-B4)*24,2) -> 10 | G4: =WEEKDAY(C4,2) -> 5 | H4: =CHOOSE(G4,"Lunes","Martes","Miércoles","Jueves","Viernes","Sábado","Domingo") -> Viernes
A5: 4 | B5: 46270.374 | C5: 46271.208 | D5: si | E5: 0 | F5: =ROUND((C5-B5)*24,2) -> 20 | G5: =WEEKDAY(C5,2) -> 7 | H5: =CHOOSE(G5,"Lunes","Martes","Miércoles","Jueves","Viernes","Sábado","Domingo") -> Domingo
A6: 5 | B6: 46270.435 | C6: 46272.435 | D6: si | E6: 0 | F6: =ROUND((C6-B6)*24,2) -> 48 | G6: =WEEKDAY(C6,2) -> 1 | H6: =CHOOSE(G6,"Lunes","Martes","Miércoles","Jueves","Viernes","Sábado","Domingo") -> Lunes
A7: 6 | B7: 46273.292 | C7: 46274.126 | D7: si | E7: 0 | F7: =ROUND((C7-B7)*24,2) -> 20 | G7: =WEEKDAY(C7,2) -> 3 | H7: =CHOOSE(G7,"Lunes","Martes","Miércoles","Jueves","Viernes","Sábado","Domingo") -> Miércoles
A8: 7 | B8: 46273.462 | C8: 46275.462 | D8: si | E8: 0 | F8: =ROUND((C8-B8)*24,2) -> 48 | G8: =WEEKDAY(C8,2) -> 4 | H8: =CHOOSE(G8,"Lunes","Martes","Miércoles","Jueves","Viernes","Sábado","Domingo") -> Jueves
A9: 8 | B9: 46276.529 | C9: 46276.946 | D9: no | E9: 3 | F9: =ROUND((C9-B9)*24,2) -> 10 | G9: =WEEKDAY(C9,2) -> 5 | H9: =CHOOSE(G9,"Lunes","Martes","Miércoles","Jueves","Viernes","Sábado","Domingo") -> Viernes
A10: 9 | B10: 46278.482 | C10: 46278.732 | D10: si | E10: 0 | F10: =ROUND((C10-B10)*24,2) -> 6 | G10: =WEEKDAY(C10,2) -> 7 | H10: =CHOOSE(G10,"Lunes","Martes","Miércoles","Jueves","Viernes","Sábado","Domingo") -> Domingo
A11: 10 | B11: 46278.205 | C11: 46280.205 | D11: si | E11: 0 | F11: =ROUND((C11-B11)*24,2) -> 48 | G11: =WEEKDAY(C11,2) -> 2 | H11: =CHOOSE(G11,"Lunes","Martes","Miércoles","Jueves","Viernes","Sábado","Domingo") -> Martes
A12: 11 | B12: 46280.608 | C12: 46281.441 | D12: si | E12: 0 | F12: =ROUND((C12-B12)*24,2) -> 20 | G12: =WEEKDAY(C12,2) -> 3 | H12: =CHOOSE(G12,"Lunes","Martes","Miércoles","Jueves","Viernes","Sábado","Domingo") -> Miércoles
A13: 12 | B13: 46282.356 | C13: 46282.94 | D13: si | E13: 0 | F13: =ROUND((C13-B13)*24,2) -> 14 | G13: =WEEKDAY(C13,2) -> 4 | H13: =CHOOSE(G13,"Lunes","Martes","Miércoles","Jueves","Viernes","Sábado","Domingo") -> Jueves
A14: 13 | B14: 46283.978 | C14: 46284.561 | D14: no | E14: 2 | F14: =ROUND((C14-B14)*24,2) -> 14 | G14: =WEEKDAY(C14,2) -> 6 | H14: =CHOOSE(G14,"Lunes","Martes","Miércoles","Jueves","Viernes","Sábado","Domingo") -> Sábado
A15: 14 | B15: 46285.619 | C15: 46286.202 | D15: si | E15: 0 | F15: =ROUND((C15-B15)*24,2) -> 14 | G15: =WEEKDAY(C15,2) -> 1 | H15: =CHOOSE(G15,"Lunes","Martes","Miércoles","Jueves","Viernes","Sábado","Domingo") -> Lunes
... A21: 20 | B21: 46293.042 | C21: 46295.209 | D21: si | E21: 0 | F21: =ROUND((C21-B21)*24,2) -> 52 | G21: =WEEKDAY(C21,2) -> 3 | H21: =CHOOSE(G21,"Lunes","Martes","Miércoles","Jueves","Viernes","Sábado","Domingo") -> Miércoles

Sheet Cálculos DORA
A1: Métricas DORA – Startup de citas médicas
A3: Parámetro | B3: Valor | C3: Nota
A4: Días del periodo | B4: 28 | C4: Dato del enunciado (datos/LEEME.md: 28 días).
A5: Total de despliegues | B5: =COUNTA(Datos!A2:A21) -> 20 | C5: Cuenta de filas del CSV.
A6: Despliegues fallidos | B6: =COUNTIF(Datos!D2:D21,"no") -> 4 | C6: Filas con exitoso = "no".
A8: Métrica DORA | B8: Resultado | C8: Cálculo / fórmula
A9: Frecuencia de despliegue (por día) | B9: =B5/B4 -> 0.71428571 | C9: Total despliegues ÷ días = 20 ÷ 28
A10: Frecuencia de despliegue (por semana) | B10: =B5/(B4/7) -> 5 | C10: Total despliegues ÷ semanas = 20 ÷ 4
A11: Lead time de cambios – mediana (h) | B11: =MEDIAN(Datos!F2:F21) -> 20 | C11: Mediana de (fecha_despliegue − fecha_commit) en horas
A12: Lead time de cambios – media (h) [referencia] | B12: =AVERAGE(Datos!F2:F21) -> 24.7 | C12: Solo referencia; DORA usa la mediana
A13: Tasa de fallo de cambios | B13: =B6/B5 -> 0.2 | C13: Fallidos ÷ total = 4 ÷ 20
A14: Tiempo medio de recuperación – MTTR (h) | B14: =AVERAGEIF(Datos!D2:D21,"no",Datos!E2:E21) -> 4.5 | C14: Promedio de horas_recuperacion solo en despliegues fallidos = 18 ÷ 4
A17: Lead time ordenado (para verificar la mediana)
A18: Posición | B18: Lead time (h) | C18: Comentario
A19: 1 | B19: =SMALL(Datos!$F$2:$F$21,A19) -> 6
A20: 2 | B20: =SMALL(Datos!$F$2:$F$21,A20) -> 6
A21: 3 | B21: =SMALL(Datos!$F$2:$F$21,A21) -> 10
A22: 4 | B22: =SMALL(Datos!$F$2:$F$21,A22) -> 10
A23: 5 | B23: =SMALL(Datos!$F$2:$F$21,A23) -> 10
A24: 6 | B24: =SMALL(Datos!$F$2:$F$21,A24) -> 14
A25: 7 | B25: =SMALL(Datos!$F$2:$F$21,A25) -> 14
A26: 8 | B26: =SMALL(Datos!$F$2:$F$21,A26) -> 14
A27: 9 | B27: =SMALL(Datos!$F$2:$F$21,A27) -> 14
A28: 10 | B28: =SMALL(Datos!$F$2:$F$21,A28) -> 20 | C28: Valor central (posición 10 u 11)
A29: 11 | B29: =SMALL(Datos!$F$2:$F$21,A29) -> 20 | C29: Valor central (posición 10 u 11)
A30: 12 | B30: =SMALL(Datos!$F$2:$F$21,A30) -> 20
A31: 13 | B31: =SMALL(Datos!$F$2:$F$21,A31) -> 20
A32: 14 | B32: =SMALL(Datos!$F$2:$F$21,A32) -> 20
A33: 15 | B33: =SMALL(Datos!$F$2:$F$21,A33) -> 48
A34: 16 | B34: =SMALL(Datos!$F$2:$F$21,A34) -> 48
A35: 17 | B35: =SMALL(Datos!$F$2:$F$21,A35) -> 48
A36: 18 | B36: =SMALL(Datos!$F$2:$F$21,A36) -> 48
A37: 19 | B37: =SMALL(Datos!$F$2:$F$21,A37) -> 52
A38: 20 | B38: =SMALL(Datos!$F$2:$F$21,A38) -> 52
A39: Mediana = promedio de posiciones 10 y 11 | B39: =(B28+B29)/2 -> 20 | C39: =IF(B39=B11,"Coincide con MEDIAN ✔","Revisar") -> Coincide con MEDIAN ✔
A41: Despliegues fallidos y recuperación
A42: id | B42: Horas de recuperación | C42: Día del despliegue
A43: =Datos!A4 -> 3 | B43: =Datos!E4 -> 5 | C43: =Datos!H4 -> Viernes
A44: =Datos!A9 -> 8 | B44: =Datos!E9 -> 3 | C44: =Datos!H9 -> Viernes
A45: =Datos!A14 -> 13 | B45: =Datos!E14 -> 2 | C45: =Datos!H14 -> Sábado
...

Sheet Métricas por enfoque
A1: Métricas por enfoque y atributo ISO/IEC 25010
A3: Enfoque | B3: Métrica | C3: Cómo se mide | D3: Meta sugerida | E3: Atributo ISO 25010 que respalda
A4: Scrum | B4: Defectos escapados por sprint | C4: Bugs detectados en producción por cada iteración de 2 semanas | D4: Tendencia a la baja; ≤ 2 por sprint | E4: Fiabilidad (madurez)
A5: Kanban | B5: Cycle time por tarjeta | C5: Tiempo desde "En progreso" hasta "Hecho"; vigilar cumplimiento del límite WIP | D5: Estable y ≤ 3 días | E5: Eficiencia de desempeño / Mantenibilidad (facilidad de modificación)
A6: XP | B6: Cobertura de pruebas unitarias | C6: pytest --cov=src (líneas cubiertas ÷ líneas totales) | D6: ≥ 80 % | E6: Mantenibilidad (capacidad de ser probado)
A7: DevOps | B7: Tasa de fallo de cambios | C7: Despliegues fallidos ÷ despliegues totales | D7: < 15 % (hoy: ver hoja Cálculos DORA) | E7: Fiabilidad (disponibilidad y recuperabilidad)
A9: Valor actual de la tasa de fallo (DevOps) | B9: ='Cálculos DORA'!B13 -> 0.2
